Workbook

Sheet Data sources
A1: Full data needed for numerical simulation
A3: Emitter bids should be positive. Carbon remover bids should be negative.
B5: Type | C5: Chemical | D5: Waut source | E5: Source2 | F5: Source3 | G5: $Bidapt source | H5: Kg Qapt source
A6: On hand | B6: Emission | C6: Carbon (not CO2) | D6: Hector | G6: Sheet Bids | H6: Sheet Bids
A7: On hand | B7: Emission | C7: CH4 | D7: Hector | G7: mmc1.xlsx | H7: mmc1.xlsx
A8: On hand | B8: Emission | C8: NO2 | D8: Hector | G8: mmc1.xlsx | H8: mmc1.xlsx
A9: On hand | B9: Emission | C9: HFC-23 | D9: Hector | G9: mmc2.xlsx | H9: mmc2.xlsx
A10: On hand | B10: Emission | C10: HFC-32 | D10: Hector | G10: mmc2.xlsx | H10: mmc2.xlsx
A11: On hand | B11: Emission | C11: HFC-43_10 | D11: Hector | G11: mmc2.xlsx | H11: mmc2.xlsx
A12: On hand | B12: Emission | C12: HFC-125 | D12: Hector | G12: mmc2.xlsx | H12: mmc2.xlsx
A13: On hand | B13: Emission | C13: HFC-134a | D13: Hector | G13: mmc2.xlsx | H13: mmc2.xlsx
A14: On hand | B14: Emission | C14: HFC-143a | D14: Hector | G14: mmc2.xlsx | H14: mmc2.xlsx
A15: On hand | B15: Emission | C15: HFC-152a | D15: Hector | G15: mmc2.xlsx | H15: mmc2.xlsx
A16: On hand | B16: Emission | C16: HFC-227ea | D16: Hector | G16: mmc2.xlsx | H16: mmc2.xlsx
A17: On hand | B17: Emission | C17: HFC-236fa | D17: Hector | G17: mmc2.xlsx | H17: mmc2.xlsx
... A25: On hand | B25: Abatement | C25: Agriculture | D25: Smith, P. et al. (2014), “Agriculture, Forestry and Other Land Use (AFOLU)”, in Edenhofer, O., et al. (eds.), Climate Change 2014: Mitigation of Climate Change. Contribution of Working Group III to the Fifth Assessment Report of the Intergovernmental Panel on Climate Change, Cambridge University Press, Cambridge, United Kingdom and New York, NY, USA. | G25: Sheet Forestry | H25: Sheet Forestry
A27: To do list, must be brought into Python.
A28: Done | B28: Agriculture | C28: bids
A29: Done | B29: Agriculture | C29: warming | F29: Bold are on the IPCC list of GHG
A30: Done | B30: C2F6 | C30: bids | F30: In Pulse | G30: In Bids
A31: Done | B31: C2F6 | C31: warming | F31: C2F6 | G31: C2F6
A32: Done | B32: CF4 | C32: bids | F32: CF4 | G32: CF4
A33: Done | B33: CF4 | C33: warming | F33: ffi | G33: Carbon
A34: Done | B34: CH4 | C34: bids | E34: Banned in US | F34: HFC-125 | G34: HFC-125
A35: Done | B35: CH4 | C35: warming | F35: HFC-134a | G35: HFC-134a
A36: Done | B36: Carbon | C36: bids | F36: HFC-143a | G36: HFC-143a
A37: Done | B37: Carbon | C37: warming | F37: SF6 | G37: SF6
A38: Done | B38: Forestry | C38: bids | F38: CH4 | G38: CH4
A39: Done | B39: Forestry | C39: warming | F39: SO2 | G39: To do
A40: Done | B40: HFC-125 | C40: bids | F40: N2O | G40: N2O
A41: Done | B41: HFC-125 | C41: warming | F41: BC
A42: Done | B42: HFC-134a | C42: bids | F42: CFC11 | H42: Controlled
A43: Done | B43: HFC-134a | C43: warming | F43: CFC12 | H43: Controlled
A44: Done | B44: HFC-143a | C44: bids | F44: CO
A45: Done | B45: HFC-143a | C45: warming | F45: HCF22
A46: Done | B46: N2O | C46: bids | F46: NMVOC
A47: Done | B47: N2O | C47: warming | F47: OC
A48: Done | B48: SF6 | C48: bids | G48: C6F14
A49: Done | B49: SF6 | C49: warming | G49: HFC-152a
A50: No bids, climate cooler, | B50: SO2 | C50: bids | G50: HFC-227ea | H50: Controlled
...

Sheet Initial burdens
B1: Initial quantities in the atmosphere
A2: Molecules in the atmosphere | C2: =1.04*10^44 -> 1.04e+44
A3: Avogadro's number | C3: 6.0221409e+23
A4: Moles in atmosphere | C4: =C2/C3 -> 1.7269606e+20
D5: https://www.esrl.noaa.gov/gmd/aggi/aggi.html
A6: Pollutant | B6: Units | C6: Emissions in 2020 | D6: ppm in 2020 | E6: ppm in 1920 | F6: Molecular weight g/mol | G6: Quantity in atmosphere
A7: Carbon (ffi) | B7: GtC/yr | D7: 420 | E7: 303.3 | G7: =(D7-E7)*2.13 -> 248.571 | H7: gTons C. According to https://cdiac.ess-dive.lbl.gov/pns/convert.html, 1 ppm by volume of atmosphere CO2 = 2.13 Gt C
A8: CH4 | B8: MtCH4/yr | C8: 256.7679 | D8: 1.86 | F8: 16.043 | G8: =$C$2/$C$3*D8*F8/10^18 -> 5153.2469 | H8: mtons, guesstimated from Hector.
A9: N2O | B9: MtN2O-N/yr | C9: 7.3634 | D9: =335/1000 -> 0.335 | F9: 44.01 | G9: =$C$2/$C$3*D9*F9/10^18 -> 2546.1184 | H9: mtons, https://www.ipcc.ch/site/assets/uploads/2018/03/TAR-04.pdf, and Ravishankara, A. R.; Daniel, J. S.; Portmann, R. W. (2009). "Nitrous Oxide (N2O): The Dominant Ozone-Depleting Substance Emitted in the 21st Century". Science. 326 (5949): 123–5.
A10: CF4 | B10: kt/yr | C10: 12.2168 | D10: =74/10^6 -> 7.4e-05 | F10: 88.043 | G10: =$C$2/$C$3*D10*F10/10^15 -> 1125.1463 | H10: ktons, https://www.ocwd.com/media/7878/appendix-a-air-quality-and-ghg-impact-analysis.pdf
A11: C2F6 | B11: kt/yr | C11: 5.3983 | D11: =2.6/10^6 -> 2.6e-06 | F11: 138.01 | G11: =$C$2/$C$3*D11*F11/10^15 -> 61.967836 | H11: ktons, https://www.ocwd.com/media/7878/appendix-a-air-quality-and-ghg-impact-analysis.pdf
A12: HFC125 | B12: kt/yr | C12: 89.349 | D12: =28.035/10^6 -> 2.8035e-05 | F12: 120.02 | G12: =$C$2/$C$3*D12*F12/10^15 -> 581.08091 | H12: ktons, extrapolated from https://cdiac.ess-dive.lbl.gov/ftp/ale_gage_Agage/AGAGE/gc-ms-medusa/monthly/CGO-medusa.mon
A13: HFC134a | B13: kt/yr | C13: 173.879 | D13: =105/10^6 -> 0.000105 | F13: 102.03 | G13: =$C$2/$C$3*D13*F13/10^15 -> 1850.1188 | H13: ktons, extrapolated from https://cdiac.ess-dive.lbl.gov/ftp/ale_gage_Agage/AGAGE/gc-ms-medusa/monthly/CGO-medusa.mon
A14: HFC143a | B14: kt/yr | C14: 64.3741 | D14: =24.26/10^6 -> 2.426e-05 | F14: 84.04 | G14: =$C$2/$C$3*D14*F14/10^15 -> 352.09452 | H14: ktons, extrapolated from https://cdiac.ess-dive.lbl.gov/ftp/ale_gage_Agage/AGAGE/gc-ms-medusa/monthly/CGO-medusa.mon
A15: SF6 | B15: kt/yr | C15: 2.2441 | D15: =10.1/10^9 -> 1.01e-08 | F15: 146.06 | G15: =$C$2/$C$3*D15*F15/10^15 -> 0.25476226 | H15: ktons, extrapolated from https://cdiac.ess-dive.lbl.gov/ftp/ale_gage_Agage/AGAGE/gc-ms-medusa/monthly/CGO-medusa.mon

Sheet Atm concs
A1: From https://cdiac.ess-dive.lbl.gov/ftp/ale_gage_Agage/AGAGE/gc-ms-medusa/monthly/
A2: monthly mean of baseline data | B2: created: | C2: 15-Aug-2017
A3: GC-MS Medusa | B3: Cape Grim | C3: Tasmania | D3: Lat.: | E3: -40.68 | F3: 40.68S | G3: Lon.: | H3: 144.69 | I3: 144.69E | J3: Alt: | K3: 94 | L3: m above sea level
A5: CREDIT FOR USE: This is a formal notification for data users.
A6: For scientific purposes access to these data is unlimited and
A7: provided without charge. By their use you accept that an offer
A8: of co-authorship will be made through personal contact with the
A9: data providers or owners whenever substantial use is made of
A10: their data. In all cases an acknowledgement must be made to the
A11: data providers or owners and the data centre when these data are
A12: used within a publication.
A13: CONTACT POINT: paul.krummel@csiro.au; paul.fraser@csiro.au; raywang@eas.gatech.edu
A15: scale: | B15: --- | C15: --- | D15: --- | E15: SIO-05 | F15: --- | G15: --- | H15: SIO-05 | I15: --- | J15: --- | K15: SIO-05 | L15: --- | M15: --- | N15: SIO-05 | O15: --- | P15: --- | Q15: SIO-05 | R15: --- | S15: --- | T15: SIO-05 | U15: --- | V15: --- | W15: SIO-05 | X15: --- | Y15: --- | Z15: SIO-05 | AA15: --- | AB15: --- | AC15: SIO-05 | AD15: --- | AE15: --- | AF15: SIO-14 | AG15: --- | AH15: --- | AI15: UB-98 | AJ15: --- | AK15: --- | AL15: NOAA2003B | AM15: --- | AN15: --- | AO15: SIO-05 | AP15: --- | AQ15: --- | AR15: SIO-05 | AS15: --- | AT15: --- | AU15: SIO-98 | AV15: --- | AW15: --- | AX15: SIO-05 | AY15: --- | AZ15: --- | BA15: SIO-14 | BB15: --- | BC15: --- | BD15: SIO-07 | BE15: --- | BF15: --- | BG15: SIO-14 | BH15: --- | BI15: --- | BJ15: SIO-07 | BK15: --- | BL15: --- | BM15: SIO-07 | BN15: --- | BO15: --- | BP15: SIO-07 | BQ15: --- | BR15: --- | BS15: SIO-05 | BT15: --- | BU15: --- | BV15: SIO-14 | BW15: --- | BX15: --- | BY15: SIO-14 | BZ15: --- | CA15: --- | CB15: SIO-14 | CC15: --- | CD15: --- | CE15: SIO-05 | CF15: --- | CG15: --- | CH15: SIO-05 | CI15: --- | CJ15: --- | CK15: SIO-14 | CL15: --- | CM15: --- | CN15: SIO-12 | CO15: --- | CP15: --- | CQ15: SIO-05 | CR15: --- | CS15: --- | CT15: SIO-05 | CU15: --- | CV15: --- | CW15: SIO-05 | CX15: --- | CY15: --- | CZ15: SIO-07 | DA15: --- | DB15: --- | DC15: SIO-07 | DD15: --- | DE15: --- | DF15: SIO-14 | DG15: ---
A16: unit: | B16: --- | C16: --- | D16: --- | E16: SIO-05 | F16: --- | G16: --- | H16: ppt | I16: --- | J16: --- | K16: ppt | L16: --- | M16: --- | N16: ppt | O16: --- | P16: --- | Q16: ppt | R16: --- | S16: --- | T16: ppt | U16: --- | V16: --- | W16: ppt | X16: --- | Y16: --- | Z16: ppt | AA16: --- | AB16: --- | AC16: ppt | AD16: --- | AE16: --- | AF16: ppt | AG16: --- | AH16: --- | AI16: ppt | AJ16: --- | AK16: --- | AL16: ppt | AM16: --- | AN16: --- | AO16: ppt | AP16: --- | AQ16: --- | AR16: ppt | AS16: --- | AT16: --- | AU16: ppt | AV16: --- | AW16: --- | AX16: ppt | AY16: --- | AZ16: --- | BA16: ppt | BB16: --- | BC16: --- | BD16: ppt | BE16: --- | BF16: --- | BG16: ppt | BH16: --- | BI16: --- | BJ16: ppt | BK16: --- | BL16: --- | BM16: ppt | BN16: --- | BO16: --- | BP16: ppt | BQ16: --- | BR16: --- | BS16: ppt | BT16: --- | BU16: --- | BV16: ppt | BW16: --- | BX16: --- | BY16: ppt | BZ16: --- | CA16: --- | CB16: ppt | CC16: --- | CD16: --- | CE16: ppt | CF16: --- | CG16: --- | CH16: ppt | CI16: --- | CJ16: --- | CK16: ppt | CL16: --- | CM16: --- | CN16: ppt | CO16: --- | CP16: --- | CQ16: ppt | CR16: --- | CS16: --- | CT16: ppt | CU16: --- | CV16: --- | CW16: ppt | CX16: --- | CY16: --- | CZ16: ppt | DA16: --- | DB16: --- | DC16: ppt | DD16: --- | DE16: --- | DF16: ppt | DG16: ---
A17: time | B17: MM | C17: YYYY | D17: num | E17: HFC-134a | F17: std. | G17: num | H17: HCFC-22 | I17: std. | J17: num | K17: HCFC-141b | L17: std. | M17: num | N17: HCFC-142b | O17: std. | P17: num | Q17: CH3Cl | R17: std. | S17: num | T17: CH3Br | U17: std. | V17: num | W17: H-1211 | X17: std. | Y17: num | Z17: H-1301 | AA17: std. | AB17: num | AC17: HFC-152a | AD17: std. | AE17: num | AF17: CH2Cl2 | AG17: std. | AH17: num | AI17: TCE | AJ17: std. | AK17: num | AL17: PCE | AM17: std. | AN17: num | AO17: CFC-113 | AP17: std. | AQ17: num | AR17: CH3CCl3 | AS17: std. | AT17: num | AU17: CHCl3 | AV17: std. | AW17: num | AX17: SF6 | AY17: std. | AZ17: num | BA17: HFC-365mfc | BB17: std. | BC17: num | BD17: SO2F2 | BE17: std. | BF17: num | BG17: HFC-125 | BH17: std. | BI17: num | BJ17: HFC-23 | BK17: std. | BL17: num | BM17: PFC-116 | BN17: std. | BO17: num | BP17: PFC-218 | BQ17: std. | BR17: num | BS17: PFC-14 | BT17: std. | BU17: num | BV17: HFC-227ea | BW17: std. | BX17: num | BY17: HFC-245fa | BZ17: std. | CA17: num | CB17: HFC-236fa | CC17: std. | CD17: num | CE17: CFC-115 | CF17: std. | CG17: num | CH17: CFC-114 | CI17: std. | CJ17: num | CK17: HFC4310mee | CL17: std. | CM17: num | CN17: NF3 | CO17: std. | CP17: num | CQ17: CFC-11 | CR17: std. | CS17: num | CT17: CFC-12 | CU17: std. | CV17: num | CW17: CCl4 | CX17: std. | CY17: num | CZ17: HFC-32 | DA17: std. | DB17: num | DC17: HFC-143a | DD17: std. | DE17: num | DF17: H-2402 | DG17: std.
A18: 2004.042 | B18: 1 | C18: 2004 | D18: 80 | E18: 24.449 | F18: 0.175 | G18: 82 | H18: 152.117 | I18: 0.6 | J18: 88 | K18: 15.702 | L18: 0.086 | M18: 88 | N18: 14.048 | O18: 0.057 | P18: 24 | Q18: 501.083 | R18: 2.201 | S18: 40 | T18: 6.95 | U18: 0.123 | V18: 86 | W18: 4.183 | X18: 0.045 | Y18: 91 | Z18: 2.98 | AA18: 0.048 | AB18: 85 | AC18: 1.653 | AD18: 0.046 | AE18: 75 | AF18: 7.173 | AG18: 0.111 | AH18: 0 | AI18: 0 | AJ18: 0 | AK18: 60 | AL18: 0.373 | AM18: 0.015 | AN18: 88 | AO18: 79.547 | AP18: 0.154 | AQ18: 90 | AR18: 23.627 | AS18: 0.299 | AT18: 23 | AU18: 4.602 | AV18: 0.144 | AW18: 0 | AX18: 0 | AY18: 0 | AZ18: 0 | BA18: 0 | BB18: 0 | BC18: 0 | BD18: 0 | BE18: 0 | BF18: 0 | BG18: 0 | BH18: 0 | BI18: 0 | BJ18: 0 | BK18: 0 | BL18: 0 | BM18: 0 | BN18: 0 | BO18: 92 | BP18: 0.37 | BQ18: 0.012 | BR18: 0 | BS18: 0 | BT18: 0 | BU18: 0 | BV18: 0 | BW18: 0 | BX18: 0 | BY18: 0 | BZ18: 0 | CA18: 0 | CB18: 0 | CC18: 0 | CD18: 88 | CE18: 8.315 | CF18: 0.053 | CG18: 88 | CH18: 16.572 | CI18: 0.045 | CJ18: 0 | CK18: 0 | CL18: 0 | CM18: 0 | CN18: 0 | CO18: 0 | CP18: 0 | CQ18: 0 | CR18: 0 | CS18: 0 | CT18: 0 | CU18: 0 | CV18: 0 | CW18: 0 | CX18: 0 | CY18: 0 | CZ18: 0 | DA18: 0 | DB18: 86 | DC18: 4.072 | DD18: 0.083 | DE18: 82 | DF18: 0.475 | DG18: 0.007
A19: 2004.125 | B19: 2 | C19: 2004 | D19: 197 | E19: 24.515 | F19: 0.182 | G19: 207 | H19: 152.065 | I19: 0.576 | J19: 219 | K19: 15.719 | L19: 0.086 | M19: 220 | N19: 14.041 | O19: 0.049 | P19: 109 | Q19: 495.006 | R19: 4.471 | S19: 161 | T19: 6.919 | U19: 0.172 | V19: 221 | W19: 4.184 | X19: 0.045 | Y19: 218 | Z19: 2.985 | AA19: 0.049 | AB19: 216 | AC19: 1.635 | AD19: 0.041 | AE19: 199 | AF19: 6.996 | AG19: 0.118 | AH19: 0 | AI19: 0 | AJ19: 0 | AK19: 169 | AL19: 0.345 | AM19: 0.015 | AN19: 220 | AO19: 79.454 | AP19: 0.156 | AQ19: 221 | AR19: 23.403 | AS19: 0.304 | AT19: 94 | AU19: 4.504 | AV19: 0.131 | AW19: 0 | AX19: 0 | AY19: 0 | AZ19: 0 | BA19: 0 | BB19: 0 | BC19: 0 | BD19: 0 | BE19: 0 | BF19: 188 | BG19: 2.753 | BH19: 0.032 | BI19: 0 | BJ19: 0 | BK19: 0 | BL19: 0 | BM19: 0 | BN19: 0 | BO19: 219 | BP19: 0.372 | BQ19: 0.012 | BR19: 0 | BS19: 0 | BT19: 0 | BU19: 0 | BV19: 0 | BW19: 0 | BX19: 0 | BY19: 0 | BZ19: 0 | CA19: 0 | CB19: 0 | CC19: 0 | CD19: 222 | CE19: 8.314 | CF19: 0.053 | CG19: 223 | CH19: 16.56 | CI19: 0.038 | CJ19: 0 | CK19: 0 | CL19: 0 | CM19: 0 | CN19: 0 | CO19: 0 | CP19: 0 | CQ19: 0 | CR19: 0 | CS19: 0 | CT19: 0 | CU19: 0 | CV19: 0 | CW19: 0 | CX19: 0 | CY19: 161 | CZ19: 0.479 | DA19: 0.035 | DB19: 205 | DC19: 4.088 | DD19: 0.075 | DE19: 221 | DF19: 0.473 | DG19: 0.007
A20: 2004.208 | B20: 3 | C20: 2004 | D20: 254 | E20: 24.888 | F20: 0.244 | G20: 295 | H20: 152.54 | I20: 0.674 | J20: 293 | K20: 15.829 | L20: 0.112 | M20: 294 | N20: 14.106 | O20: 0.069 | P20: 147 | Q20: 497.056 | R20: 5.791 | S20: 228 | T20: 6.944 | U20: 0.166 | V20: 305 | W20: 4.193 | X20: 0.044 | Y20: 302 | Z20: 2.969 | AA20: 0.048 | AB20: 302 | AC20: 1.674 | AD20: 0.045 | AE20: 280 | AF20: 7.25 | AG20: 0.226 | AH20: 0 | AI20: 0 | AJ20: 0 | AK20: 181 | AL20: 0.38 | AM20: 0.039 | AN20: 306 | AO20: 79.374 | AP20: 0.18 | AQ20: 316 | AR20: 22.885 | AS20: 0.346 | AT20: 143 | AU20: 4.505 | AV20: 0.186 | AW20: 0 | AX20: 0 | AY20: 0 | AZ20: 0 | BA20: 0 | BB20: 0 | BC20: 0 | BD20: 0 | BE20: 0 | BF20: 278 | BG20: 2.762 | BH20: 0.035 | BI20: 0 | BJ20: 0 | BK20: 0 | BL20: 0 | BM20: 0 | BN20: 0 | BO20: 306 | BP20: 0.374 | BQ20: 0.011 | BR20: 0 | BS20: 0 | BT20: 0 | BU20: 0 | BV20: 0 | BW20: 0 | BX20: 0 | BY20: 0 | BZ20: 0 | CA20: 0 | CB20: 0 | CC20: 0 | CD20: 313 | CE20: 8.329 | CF20: 0.058 | CG20: 304 | CH20: 16.558 | CI20: 0.044 | CJ20: 0 | CK20: 0 | CL20: 0 | CM20: 0 | CN20: 0 | CO20: 0 | CP20: 0 | CQ20: 0 | CR20: 0 | CS20: 0 | CT20: 0 | CU20: 0 | CV20: 0 | CW20: 0 | CX20: 0 | CY20: 284 | CZ20: 0.5 | DA20: 0.038 | DB20: 284 | DC20: 4.165 | DD20: 0.078 | DE20: 307 | DF20: 0.473 | DG20: 0.007
A21: 2004.292 | B21: 4 | C21: 2004 | D21: 230 | E21: 25.344 | F21: 0.271 | G21: 253 | H21: 153.052 | I21: 0.672 | J21: 257 | K21: 15.939 | L21: 0.104 | M21: 247 | N21: 14.134 | O21: 0.062 | P21: 83 | Q21: 509.51 | R21: 7.654 | S21: 164 | T21: 7.029 | U21: 0.162 | V21: 267 | W21: 4.206 | X21: 0.044 | Y21: 260 | Z21: 2.976 | AA21: 0.047 | AB21: 253 | AC21: 1.743 | AD21: 0.063 | AE21: 200 | AF21: 7.879 | AG21: 0.27 | AH21: 0 | AI21: 0 | AJ21: 0 | AK21: 176 | AL21: 0.493 | AM21: 0.045 | AN21: 268 | AO21: 79.352 | AP21: 0.2 | AQ21: 271 | AR21: 22.54 | AS21: 0.308 | AT21: 73 | AU21: 4.882 | AV21: 0.168 | AW21: 0 | AX21: 0 | AY21: 0 | AZ21: 0 | BA21: 0 | BB21: 0 | BC21: 0 | BD21: 0 | BE21: 0 | BF21: 229 | BG21: 2.795 | BH21: 0.034 | BI21: 0 | BJ21: 0 | BK21: 0 | BL21: 76 | BM21: 3.462 | BN21: 0.03 | BO21: 254 | BP21: 0.371 | BQ21: 0.012 | BR21: 0 | BS21: 0 | BT21: 0 | BU21: 0 | BV21: 0 | BW21: 0 | BX21: 0 | BY21: 0 | BZ21: 0 | CA21: 0 | CB21: 0 | CC21: 0 | CD21: 274 | CE21: 8.333 | CF21: 0.053 | CG21: 270 | CH21: 16.575 | CI21: 0.04 | CJ21: 0 | CK21: 0 | CL21: 0 | CM21: 0 | CN21: 0 | CO21: 0 | CP21: 0 | CQ21: 0 | CR21: 0 | CS21: 0 | CT21: 0 | CU21: 0 | CV21: 0 | CW21: 0 | CX21: 0 | CY21: 188 | CZ21: 0.521 | DA21: 0.041 | DB21: 240 | DC21: 4.216 | DD21: 0.071 | DE21: 270 | DF21: 0.471 | DG21: 0.007
A22: 2004.375 | B22: 5 | C22: 2004 | D22: 265 | E22: 25.865 | F22: 0.255 | G22: 292 | H22: 153.979 | I22: 0.738 | J22: 296 | K22: 16.086 | L22: 0.11 | M22: 316 | N22: 14.193 | O22: 0.065 | P22: 146 | Q22: 517.667 | R22: 7.907 | S22: 201 | T22: 6.87 | U22: 0.167 | V22: 319 | W22: 4.203 | X22: 0.046 | Y22: 308 | Z22: 2.989 | AA22: 0.046 | AB22: 303 | AC22: 1.862 | AD22: 0.059 | AE22: 239 | AF22: 8.614 | AG22: 0.351 | AH22: 0 | AI22: 0 | AJ22: 0 | AK22: 211 | AL22: 0.624 | AM22: 0.057 | AN22: 325 | AO22: 79.299 | AP22: 0.196 | AQ22: 324 | AR22: 22.272 | AS22: 0.313 | AT22: 159 | AU22: 5.306 | AV22: 0.187 | AW22: 0 | AX22: 0 | AY22: 0 | AZ22: 0 | BA22: 0 | BB22: 0 | BC22: 0 | BD22: 0 | BE22: 0 | BF22: 272 | BG22: 2.841 | BH22: 0.04 | BI22: 0 | BJ22: 0 | BK22: 0 | BL22: 319 | BM22: 3.465 | BN22: 0.03 | BO22: 311 | BP22: 0.368 | BQ22: 0.011 | BR22: 0 | BS22: 0 | BT22: 0 | BU22: 0 | BV22: 0 | BW22: 0 | BX22: 0 | BY22: 0 | BZ22: 0 | CA22: 0 | CB22: 0 | CC22: 0 | CD22: 325 | CE22: 8.318 | CF22: 0.052 | CG22: 321 | CH22: 16.565 | CI22: 0.045 | CJ22: 0 | CK22: 0 | CL22: 0 | CM22: 0 | CN22: 0 | CO22: 0 | CP22: 0 | CQ22: 0 | CR22: 0 | CS22: 0 | CT22: 0 | CU22: 0 | CV22: 0 | CW22: 0 | CX22: 0 | CY22: 303 | CZ22: 0.562 | DA22: 0.041 | DB22: 278 | DC22: 4.269 | DD22: 0.078 | DE22: 321 | DF22: 0.467 | DG22: 0.007
A23: 2004.458 | B23: 6 | C23: 2004 | D23: 182 | E23: 26.261 | F23: 0.214 | G23: 206 | H23: 154.923 | I23: 0.728 | J23: 212 | K23: 16.212 | L23: 0.116 | M23: 216 | N23: 14.253 | O23: 0.06 | P23: 127 | Q23: 527.94 | R23: 6.121 | S23: 172 | T23: 6.795 | U23: 0.134 | V23: 219 | W23: 4.218 | X23: 0.046 | Y23: 208 | Z23: 2.989 | AA23: 0.048 | AB23: 212 | AC23: 1.95 | AD23: 0.052 | AE23: 139 | AF23: 9.302 | AG23: 0.303 | AH23: 0 | AI23: 0 | AJ23: 0 | AK23: 131 | AL23: 0.759 | AM23: 0.049 | AN23: 219 | AO23: 79.209 | AP23: 0.192 | AQ23: 216 | AR23: 22.071 | AS23: 0.25 | AT23: 117 | AU23: 5.811 | AV23: 0.174 | AW23: 0 | AX23: 0 | AY23: 0 | AZ23: 0 | BA23: 0 | BB23: 0 | BC23: 0 | BD23: 0 | BE23: 0 | BF23: 186 | BG23: 2.889 | BH23: 0.036 | BI23: 0 | BJ23: 0 | BK23: 0 | BL23: 219 | BM23: 3.473 | BN23: 0.032 | BO23: 208 | BP23: 0.371 | BQ23: 0.01 | BR23: 0 | BS23: 0 | BT23: 0 | BU23: 0 | BV23: 0 | BW23: 0 | BX23: 0 | BY23: 0 | BZ23: 0 | CA23: 0 | CB23: 0 | CC23: 0 | CD23: 219 | CE23: 8.332 | CF23: 0.052 | CG23: 220 | CH23: 16.566 | CI23: 0.042 | CJ23: 0 | CK23: 0 | CL23: 0 | CM23: 0 | CN23: 0 | CO23: 0 | CP23: 0 | CQ23: 0 | CR23: 0 | CS23: 0 | CT23: 0 | CU23: 0 | CV23: 0 | CW23: 0 | CX23: 0 | CY23: 214 | CZ23: 0.578 | DA23: 0.044 | DB23: 199 | DC23: 4.368 | DD23: 0.076 | DE23: 220 | DF23: 0.469 | DG23: 0.007
A24: 2004.542 | B24: 7 | C24: 2004 | D24: 137 | E24: 26.632 | F24: 0.274 | G24: 149 | H24: 155.595 | I24: 0.813 | J24: 167 | K24: 16.34 | L24: 0.117 | M24: 173 | N24: 14.318 | O24: 0.071 | P24: 89 | Q24: 532.919 | R24: 5.033 | S24: 121 | T24: 6.702 | U24: 0.117 | V24: 176 | W24: 4.23 | X24: 0.043 | Y24: 172 | Z24: 2.997 | AA24: 0.046 | AB24: 167 | AC24: 2.013 | AD24: 0.068 | AE24: 121 | AF24: 9.904 | AG24: 0.336 | AH24: 0 | AI24: 0 | AJ24: 0 | AK24: 127 | AL24: 0.864 | AM24: 0.037 | AN24: 174 | AO24: 79.196 | AP24: 0.171 | AQ24: 177 | AR24: 21.826 | AS24: 0.265 | AT24: 82 | AU24: 6.104 | AV24: 0.135 | AW24: 0 | AX24: 0 | AY24: 0 | AZ24: 0 | BA24: 0 | BB24: 0 | BC24: 0 | BD24: 0 | BE24: 0 | BF24: 140 | BG24: 2.926 | BH24: 0.04 | BI24: 0 | BJ24: 0 | BK24: 0 | BL24: 176 | BM24: 3.493 | BN24: 0.028 | BO24: 173 | BP24: 0.375 | BQ24: 0.01 | BR24: 0 | BS24: 0 | BT24: 0 | BU24: 0 | BV24: 0 | BW24: 0 | BX24: 0 | BY24: 0 | BZ24: 0 | CA24: 0 | CB24: 0 | CC24: 0 | CD24: 173 | CE24: 8.338 | CF24: 0.056 | CG24: 174 | CH24: 16.572 | CI24: 0.04 | CJ24: 0 | CK24: 0 | CL24: 0 | CM24: 0 | CN24: 0 | CO24: 0 | CP24: 0 | CQ24: 0 | CR24: 0 | CS24: 0 | CT24: 0 | CU24: 0 | CV24: 0 | CW24: 0 | CX24: 0 | CY24: 172 | CZ24: 0.6 | DA24: 0.048 | DB24: 153 | DC24: 4.426 | DD24: 0.091 | DE24: 175 | DF24: 0.47 | DG24: 0.007
A25: 2004.625 | B25: 8 | C25: 2004 | D25: 233 | E25: 27.115 | F25: 0.229 | G25: 271 | H25: 156.549 | I25: 0.705 | J25: 283 | K25: 16.485 | L25: 0.109 | M25: 294 | N25: 14.413 | O25: 0.067 | P25: 87 | Q25: 536.077 | R25: 3.945 | S25: 156 | T25: 6.786 | U25: 0.147 | V25: 293 | W25: 4.247 | X25: 0.047 | Y25: 299 | Z25: 2.994 | AA25: 0.05 | AB25: 295 | AC25: 2.077 | AD25: 0.055 | AE25: 164 | AF25: 10.367 | AG25: 0.165 | AH25: 0 | AI25: 0 | AJ25: 0 | AK25: 194 | AL25: 0.945 | AM25: 0.026 | AN25: 296 | AO25: 78.978 | AP25: 0.228 | AQ25: 304 | AR25: 21.636 | AS25: 0.275 | AT25: 108 | AU25: 6.307 | AV25: 0.133 | AW25: 0 | AX25: 0 | AY25: 0 | AZ25: 0 | BA25: 0 | BB25: 0 | BC25: 0 | BD25: 0 | BE25: 0 | BF25: 245 | BG25: 2.977 | BH25: 0.038 | BI25: 0 | BJ25: 0 | BK25: 0 | BL25: 304 | BM25: 3.513 | BN25: 0.035 | BO25: 298 | BP25: 0.379 | BQ25: 0.013 | BR25: 0 | BS25: 0 | BT25: 0 | BU25: 0 | BV25: 0 | BW25: 0 | BX25: 0 | BY25: 0 | BZ25: 0 | CA25: 0 | CB25: 0 | CC25: 0 | CD25: 305 | CE25: 8.353 | CF25: 0.054 | CG25: 307 | CH25: 16.578 | CI25: 0.042 | CJ25: 0 | CK25: 0 | CL25: 0 | CM25: 0 | CN25: 0 | CO25: 0 | CP25: 0 | CQ25: 0 | CR25: 0 | CS25: 0 | CT25: 0 | CU25: 0 | CV25: 0 | CW25: 0 | CX25: 0 | CY25: 298 | CZ25: 0.631 | DA25: 0.047 | DB25: 268 | DC25: 4.513 | DD25: 0.08 | DE25: 307 | DF25: 0.473 | DG25: 0.008
A26: 2004.708 | B26: 9 | C26: 2004 | D26: 234 | E26: 27.555 | F26: 0.186 | G26: 291 | H26: 157.081 | I26: 0.641 | J26: 293 | K26: 16.566 | L26: 0.097 | M26: 311 | N26: 14.507 | O26: 0.055 | P26: 167 | Q26: 535.324 | R26: 3.241 | S26: 207 | T26: 6.885 | U26: 0.111 | V26: 329 | W26: 4.256 | X26: 0.046 | Y26: 322 | Z26: 2.996 | AA26: 0.046 | AB26: 321 | AC26: 2.101 | AD26: 0.054 | AE26: 242 | AF26: 10.385 | AG26: 0.126 | AH26: 0 | AI26: 0 | AJ26: 0 | AK26: 265 | AL26: 0.9 | AM26: 0.041 | AN26: 330 | AO26: 78.753 | AP26: 0.14 | AQ26: 333 | AR26: 21.32 | AS26: 0.295 | AT26: 197 | AU26: 6.33 | AV26: 0.177 | AW26: 0 | AX26: 0 | AY26: 0 | AZ26: 0 | BA26: 0 | BB26: 0 | BC26: 0 | BD26: 0 | BE26: 0 | BF26: 262 | BG26: 3.034 | BH26: 0.036 | BI26: 0 | BJ26: 0 | BK26: 0 | BL26: 330 | BM26: 3.538 | BN26: 0.031 | BO26: 317 | BP26: 0.386 | BQ26: 0.012 | BR26: 0 | BS26: 0 | BT26: 0 | BU26: 0 | BV26: 0 | BW26: 0 | BX26: 0 | BY26: 0 | BZ26: 0 | CA26: 0 | CB26: 0 | CC26: 0 | CD26: 333 | CE26: 8.356 | CF26: 0.057 | CG26: 331 | CH26: 16.572 | CI26: 0.041 | CJ26: 0 | CK26: 0 | CL26: 0 | CM26: 0 | CN26: 0 | CO26: 0 | CP26: 0 | CQ26: 0 | CR26: 0 | CS26: 0 | CT26: 0 | CU26: 0 | CV26: 0 | CW26: 0 | CX26: 0 | CY26: 309 | CZ26: 0.657 | DA26: 0.046 | DB26: 281 | DC26: 4.569 | DD26: 0.075 | DE26: 332 | DF26: 0.476 | DG26: 0.007
A27: 2004.792 | B27: 10 | C27: 2004 | D27: 188 | E27: 27.928 | F27: 0.19 | G27: 214 | H27: 157.339 | I27: 0.648 | J27: 215 | K27: 16.577 | L27: 0.088 | M27: 214 | N27: 14.559 | O27: 0.055 | P27: 94 | Q27: 535.024 | R27: 3.475 | S27: 107 | T27: 6.924 | U27: 0.086 | V27: 231 | W27: 4.259 | X27: 0.046 | Y27: 226 | Z27: 2.998 | AA27: 0.049 | AB27: 230 | AC27: 2.119 | AD27: 0.05 | AE27: 208 | AF27: 10.067 | AG27: 0.206 | AH27: 0 | AI27: 0 | AJ27: 0 | AK27: 188 | AL27: 0.799 | AM27: 0.043 | AN27: 224 | AO27: 78.725 | AP27: 0.167 | AQ27: 234 | AR27: 21.18 | AS27: 0.295 | AT27: 92 | AU27: 6.147 | AV27: 0.219 | AW27: 0 | AX27: 0 | AY27: 0 | AZ27: 0 | BA27: 0 | BB27: 0 | BC27: 0 | BD27: 0 | BE27: 0 | BF27: 208 | BG27: 3.094 | BH27: 0.034 | BI27: 0 | BJ27: 0 | BK27: 0 | BL27: 235 | BM27: 3.544 | BN27: 0.032 | BO27: 234 | BP27: 0.389 | BQ27: 0.012 | BR27: 0 | BS27: 0 | BT27: 0 | BU27: 0 | BV27: 0 | BW27: 0 | BX27: 0 | BY27: 0 | BZ27: 0 | CA27: 0 | CB27: 0 | CC27: 0 | CD27: 235 | CE27: 8.336 | CF27: 0.06 | CG27: 232 | CH27: 16.561 | CI27: 0.048 | CJ27: 0 | CK27: 0 | CL27: 0 | CM27: 0 | CN27: 0 | CO27: 0 | CP27: 0 | CQ27: 0 | CR27: 0 | CS27: 0 | CT27: 0 | CU27: 0 | CV27: 0 | CW27: 0 | CX27: 0 | CY27: 226 | CZ27: 0.656 | DA27: 0.045 | DB27: 221 | DC27: 4.599 | DD27: 0.074 | DE27: 237 | DF27: 0.473 | DG27: 0.007
A28: 2004.875 | B28: 11 | C28: 2004 | D28: 215 | E28: 28.162 | F28: 0.191 | G28: 237 | H28: 157.401 | I28: 0.573 | J28: 243 | K28: 16.548 | L28: 0.074 | M28: 248 | N28: 14.557 | O28: 0.046 | P28: 121 | Q28: 526.408 | R28: 4.564 | S28: 138 | T28: 6.889 | U28: 0.123 | V28: 251 | W28: 4.255 | X28: 0.045 | Y28: 257 | Z28: 3.01 | AA28: 0.046 | AB28: 246 | AC28: 2.075 | AD28: 0.044 | AE28: 225 | AF28: 9.333 | AG28: 0.299 | AH28: 0 | AI28: 0 | AJ28: 0 | AK28: 211 | AL28: 0.654 | AM28: 0.054 | AN28: 254 | AO28: 78.625 | AP28: 0.126 | AQ28: 253 | AR28: 20.762 | AS28: 0.323 | AT28: 123 | AU28: 5.792 | AV28: 0.185 | AW28: 0 | AX28: 0 | AY28: 0 | AZ28: 0 | BA28: 0 | BB28: 0 | BC28: 255 | BD28: 1.231 | BE28: 0.017 | BF28: 229 | BG28: 3.117 | BH28: 0.034 | BI28: 0 | BJ28: 0 | BK28: 0 | BL28: 257 | BM28: 3.547 | BN28: 0.027 | BO28: 259 | BP28: 0.389 | BQ28: 0.011 | BR28: 0 | BS28: 0 | BT28: 0 | BU28: 0 | BV28: 0 | BW28: 0 | BX28: 0 | BY28: 0 | BZ28: 0 | CA28: 0 | CB28: 0 | CC28: 0 | CD28: 259 | CE28: 8.336 | CF28: 0.057 | CG28: 250 | CH28: 16.549 | CI28: 0.04 | CJ28: 0 | CK28: 0 | CL28: 0 | CM28: 0 | CN28: 0 | CO28: 0 | CP28: 0 | CQ28: 0 | CR28: 0 | CS28: 0 | CT28: 0 | CU28: 0 | CV28: 0 | CW28: 0 | CX28: 0 | CY28: 243 | CZ28: 0.662 | DA28: 0.039 | DB28: 230 | DC28: 4.64 | DD28: 0.064 | DE28: 257 | DF28: 0.471 | DG28: 0.006
A29: 2004.958 | B29: 12 | C29: 2004 | D29: 277 | E29: 28.454 | F29: 0.157 | G29: 298 | H29: 157.218 | I29: 0.565 | J29: 274 | K29: 16.511 | L29: 0.072 | M29: 302 | N29: 14.559 | O29: 0.044 | P29: 131 | Q29: 513.703 | R29: 4.945 | S29: 158 | T29: 6.959 | U29: 0.13 | V29: 304 | W29: 4.245 | X29: 0.044 | Y29: 310 | Z29: 3.035 | AA29: 0.041 | AB29: 306 | AC29: 2.003 | AD29: 0.05 | AE29: 277 | AF29: 8.343 | AG29: 0.313 | AH29: 0 | AI29: 0 | AJ29: 0 | AK29: 249 | AL29: 0.484 | AM29: 0.049 | AN29: 294 | AO29: 78.58 | AP29: 0.124 | AQ29: 310 | AR29: 20.233 | AS29: 0.286 | AT29: 114 | AU29: 5.237 | AV29: 0.166 | AW29: 0 | AX29: 0 | AY29: 0 | AZ29: 0 | BA29: 0 | BB29: 0 | BC29: 305 | BD29: 1.233 | BE29: 0.018 | BF29: 287 | BG29: 3.147 | BH29: 0.032 | BI29: 0 | BJ29: 0 | BK29: 0 | BL29: 307 | BM29: 3.552 | BN29: 0.028 | BO29: 305 | BP29: 0.389 | BQ29: 0.012 | BR29: 0 | BS29: 0 | BT29: 0 | BU29: 0 | BV29: 0 | BW29: 0 | BX29: 0 | BY29: 0 | BZ29: 0 | CA29: 0 | CB29: 0 | CC29: 0 | CD29: 305 | CE29: 8.363 | CF29: 0.055 | CG29: 302 | CH29: 16.542 | CI29: 0.04 | CJ29: 0 | CK29: 0 | CL29: 0 | CM29: 0 | CN29: 0 | CO29: 0 | CP29: 0 | CQ29: 0 | CR29: 0 | CS29: 0 | CT29: 0 | CU29: 0 | CV29: 0 | CW29: 0 | CX29: 0 | CY29: 302 | CZ29: 0.676 | DA29: 0.041 | DB29: 290 | DC29: 4.695 | DD29: 0.067 | DE29: 305 | DF29: 0.471 | DG29: 0.007
... A170: 2016.708 | B170: 9 | C170: 2016 | D170: 147 | E170: 84.805 | F170: 0.293 | G170: 195 | H170: 228.732 | I170: 0.629 | J170: 144 | K170: 23.268 | L170: 0.06 | M170: 201 | N170: 21.908 | O170: 0.05 | P170: 76 | Q170: 533.255 | R170: 3.839 | S170: 0 | T170: 0 | U170: 0 | V170: 201 | W170: 3.531 | X170: 0.016 | Y170: 243 | Z170: 3.314 | AA170: 0.038 | AB170: 197 | AC170: 4.761 | AD170: 0.051 | AE170: 0 | AF170: 0 | AG170: 0 | AH170: 0 | AI170: 0 | AJ170: 0 | AK170: 121 | AL170: 0.476 | AM170: 0.009 | AN170: 171 | AO170: 71.078 | AP170: 0.085 | AQ170: 239 | AR170: 2.552 | AS170: 0.04 | AT170: 0 | AU170: 0 | AV170: 0 | AW170: 220 | AX170: 8.765 | AY170: 0.022 | AZ170: 192 | BA170: 0.912 | BB170: 0.014 | BC170: 204 | BD170: 2.097 | BE170: 0.017 | BF170: 149 | BG170: 19.657 | BH170: 0.103 | BI170: 229 | BJ170: 28.524 | BK170: 0.088 | BL170: 232 | BM170: 4.524 | BN170: 0.019 | BO170: 244 | BP170: 0.631 | BQ170: 0.009 | BR170: 228 | BS170: 82.358 | BT170: 0.078 | BU170: 218 | BV170: 1.184 | BW170: 0.011 | BX170: 213 | BY170: 2.189 | BZ170: 0.024 | CA170: 235 | CB170: 0.149 | CC170: 0.004 | CD170: 236 | CE170: 8.501 | CF170: 0.033 | CG170: 174 | CH170: 16.231 | CI170: 0.039 | CJ170: 236 | CK170: 0.262 | CL170: 0.007 | CM170: 240 | CN170: 1.394 | CO170: 0.02 | CP170: 0 | CQ170: 0 | CR170: 0 | CS170: 0 | CT170: 0 | CU170: 0 | CV170: 0 | CW170: 0 | CX170: 0 | CY170: 175 | CZ170: 10.943 | DA170: 0.114 | DB170: 178 | DC170: 18.533 | DD170: 0.111 | DE170: 226 | DF170: 0.404 | DG170: 0.004
A171: 2020, estimated | E171: =E170-E122+E170 -> 105.486 | AX171: =AX170-AX122+AX170 -> 10.063 | BG171: =BG170-BG122+BG170 -> 28.035 | DC171: =DC170-DC122+DC170 -> 24.26

Sheet Forestry timing
A1: How does forestry uptake carbon over time? OBSOLETE. REPLACED WITH BUSCH ET AL DATABASE. | W1: Compare IPCC SR15_Chapter4_High_Res.pdf, section 4.3.7.2:
A2: Data taken from Stavins and Richards, The cost of US forest-based carbon sequestration.pdf | W2: 500 | X2: million hectares available
A3: Note: quantities measure carbon, not carbon dioxide. See Stavins & Richards 2005, p. 38, endnote 8. | W3: 1 | X3: low Gt C/year | Y3: =1000*W3/$W$2 -> 2 | Z3: tons/hectare
A4: I chose the last 3 contract lengths to maximize average removal/year. | W4: 3.7 | X4: avg Gt C/year | Y4: =1000*W4/$W$2 -> 7.4 | Z4: tons/hectare. So my analysis of U.S. forestry is close to the middle.
A5: Carbon removal for contracts <150 years are truncated to the contract year length. | Q5: Coefficients that fit their graph | W5: 17.9 | X5: high Gt C/year | Y5: =1000*W5/$W$2 -> 35.8 | Z5: tons/hectare
A6: Hectare/acre | B6: =CONVERT(1,"us_acre","ha") -> 0.40468726 | E6: Saved as "Forestry_sequestration.csv" | Q6: 0.0001
A7: Metric tons/US ton | B7: =CONVERT(1,"ton","kg")/1000 -> 0.907185 | D7: Avg C/yr | E7: =E9/COUNTIF(E11:E166,">0") -> 2.2244546 | F7: =F9/COUNTIF(F11:F166,">0") -> 4.0863189 | G7: =G9/COUNTIF(G11:G166,">0") -> 2.3731585 | H7: =H9/COUNTIF(H11:H166,">0") -> 3.8276925 | I7: =I9/COUNTIF(I11:I166,">0") -> 1.9939868 | J7: =J9/COUNTIF(J11:J166,">0") -> 2.4143044 | K7: =K9/COUNTIF(K11:K166,">0") -> 6.3776194 | L7: =L9/COUNTIF(L11:L166,">0") -> 4.7526089 | M7: =M9/COUNTIF(M11:M166,">0") -> 3.2382288 | Q7: 0.0693
E8: Tonnes/hectare. Used to calculate $/hectare | H8: 10-year contract | I8: 10-year contract | J8: 10-year contract | K8: 24-year contract | L8: 103-year contract | M8: 55-year contract | P8: Unused | Q8: 13.71 | R8: $1.6(2019)/$1(1997)
A9: Total C tons/acre | B9: =SUM(B11:B166) -> 153.808 | C9: =SUM(C11:C166) -> 282.545 | D9: =SUM(D11:D166) -> 164.09 | E9: =SUM(E11:E166) -> 344.79047 | F9: =SUM(F11:F166) -> 633.37942 | G9: =SUM(G11:G166) -> 367.83956 | H9: =SUM(H11:H166) -> 38.276925 | I9: =SUM(I11:I166) -> 19.939868 | ... M9: =SUM(M11:M166) -> 178.10259 | P9: $2020/$1997 = | R9: =1.6*1.027 -> 1.6432
A10: Year | B10: Tons/acre/year Loblolly pine | C10: Tons/acre/year Ponderosa pine | D10: Tons/acre/year Black walnut | E10: Tonnes/hectare/year Loblolly pine | F10: Tonnes/hectare/year Ponderosa pine | G10: Tonnes/hectare/year Black walnut | H10: Tonnes/hectare/year Loblolly pine, 10 yr | I10: Tonnes/hectare/year Ponderosa pine, 10 yr | J10: Tonnes/hectare/year Black walnut, 10 yr | K10: Tonnes/hectare/year Loblolly pine, 24 yr | L10: Tonnes/hectare/year Ponderosa pine, 103 yr | M10: Tonnes/hectare/year Black walnut, 55 yr | P10: Mton CO2/year | Q10: 1997 $/ton | R10: 2019 $/ton | S10: 2019 $/tonne | T10: 2019 $/hectare Loblolly Pine | U10: 2019 $/hectare ponderosa pine | V10: 2019 $/hectare black walnut
A11: 0 | B11: 0 | C11: 0 | D11: 0 | E11: =B11*$B$7/$B$6 -> 0 | F11: =C11*$B$7/$B$6 -> 0 | G11: =D11*$B$7/$B$6 -> 0 | H11: =ROUND(B11*$B$7/$B$6,3) -> 0 | I11: =ROUND(C11*$B$7/$B$6,3) -> 0 | J11: =ROUND(D11*$B$7/$B$6,3) -> 0 | K11: =ROUND(E11*$B$7/$B$6,3) -> 0 | L11: =ROUND(F11*$B$7/$B$6,3) -> 0 | M11: =ROUND(G11*$B$7/$B$6,3) -> 0 | P11: 0 | Q11: =ROUND($Q$6*P11^2+$Q$7*P11+$Q$8,1) -> 13.7 | R11: =Q11*$R$9 -> 22.51184 | S11: =R11/$B$7 -> 24.815049 | T11: =$S11*E$9 -> 8555.9923 | U11: =$S11*F$9 -> 15717.341 | V11: =$S11*G$9 -> 9127.9568
A12: 1 | B12: 0.335 | C12: 0.22 | D12: 0.264 | E12: =B12*$B$7/$B$6 -> 0.75096748 | F12: =C12*$B$7/$B$6 -> 0.49317268 | G12: =D12*$B$7/$B$6 -> 0.59180721 | H12: =E12 -> 0.75096748 | I12: =F12 -> 0.49317268 | J12: =G12 -> 0.59180721 | K12: =E12 -> 0.75096748 | L12: =F12 -> 0.49317268 | M12: =G12 -> 0.59180721 | P12: =P11+20 -> 20 | Q12: 15 | R12: =Q12*$R$9 -> 24.648 | S12: =R12/$B$7 -> 27.169762 | T12: =$S12*E$9 -> 9367.8748 | U12: =$S12*F$9 -> 17208.768 | V12: =$S12*G$9 -> 9994.1133
A13: 2 | B13: 0.67 | C13: 0.44 | D13: 0.528 | E13: =B13*$B$7/$B$6 -> 1.501935 | F13: =C13*$B$7/$B$6 -> 0.98634535 | G13: =D13*$B$7/$B$6 -> 1.1836144 | H13: =E13 -> 1.501935 | I13: =F13 -> 0.98634535 | J13: =G13 -> 1.1836144 | K13: =E13 -> 1.501935 | L13: =F13 -> 0.98634535 | M13: =G13 -> 1.1836144 | P13: =P12+20 -> 40 | Q13: =ROUND($Q$6*P13^2+$Q$7*P13+$Q$8,1) -> 16.6 | R13: =Q13*$R$9 -> 27.27712 | S13: =R13/$B$7 -> 30.067869 | T13: =$S13*E$9 -> 10367.115 | U13: =$S13*F$9 -> 19044.37 | V13: =$S13*G$9 -> 11060.152
A14: 3 | B14: 1.005 | C14: 0.66 | D14: 0.792 | E14: =B14*$B$7/$B$6 -> 2.2529024 | F14: =C14*$B$7/$B$6 -> 1.479518 | G14: =D14*$B$7/$B$6 -> 1.7754216 | H14: =E14 -> 2.2529024 | I14: =F14 -> 1.479518 | J14: =G14 -> 1.7754216 | K14: =E14 -> 2.2529024 | L14: =F14 -> 1.479518 | M14: =G14 -> 1.7754216 | P14: =P13+20 -> 60 | Q14: =ROUND($Q$6*P14^2+$Q$7*P14+$Q$8,1) -> 18.2 | R14: =Q14*$R$9 -> 29.90624 | S14: =R14/$B$7 -> 32.965977 | T14: =$S14*E$9 -> 11366.355 | U14: =$S14*F$9 -> 20879.972 | V14: =$S14*G$9 -> 12126.191
A15: 4 | B15: 1.34 | C15: 0.88 | D15: 1.056 | E15: =B15*$B$7/$B$6 -> 3.0038699 | F15: =C15*$B$7/$B$6 -> 1.9726907 | G15: =D15*$B$7/$B$6 -> 2.3672288 | H15: =E15 -> 3.0038699 | I15: =F15 -> 1.9726907 | J15: =G15 -> 2.3672288 | K15: =E15 -> 3.0038699 | L15: =F15 -> 1.9726907 | M15: =G15 -> 2.3672288 | P15: =P14+20 -> 80 | Q15: =ROUND($Q$6*P15^2+$Q$7*P15+$Q$8,1) -> 19.9 | R15: =Q15*$R$9 -> 32.69968 | S15: =R15/$B$7 -> 36.045217 | T15: =$S15*E$9 -> 12428.047 | U15: =$S15*F$9 -> 22830.299 | V15: =$S15*G$9 -> 13258.857
A16: 5 | B16: 1.675 | C16: 1.1 | D16: 1.32 | E16: =B16*$B$7/$B$6 -> 3.7548374 | F16: =C16*$B$7/$B$6 -> 2.4658634 | G16: =D16*$B$7/$B$6 -> 2.9590361 | H16: =E16 -> 3.7548374 | I16: =F16 -> 2.4658634 | J16: =G16 -> 2.9590361 | K16: =E16 -> 3.7548374 | L16: =F16 -> 2.4658634 | M16: =G16 -> 2.9590361 | P16: =P15+20 -> 100 | Q16: =ROUND($Q$6*P16^2+$Q$7*P16+$Q$8,1) -> 21.6 | R16: =Q16*$R$9 -> 35.49312 | S16: =R16/$B$7 -> 39.124457 | T16: =$S16*E$9 -> 13489.74 | U16: =$S16*F$9 -> 24780.626 | V16: =$S16*G$9 -> 14391.523
A17: 6 | B17: 1.92 | C17: 1.106 | D17: 1.334 | E17: =B17*$B$7/$B$6 -> 4.3040524 | F17: =C17*$B$7/$B$6 -> 2.4793135 | G17: =D17*$B$7/$B$6 -> 2.9904198 | H17: =E17 -> 4.3040524 | I17: =F17 -> 2.4793135 | J17: =G17 -> 2.9904198 | K17: =E17 -> 4.3040524 | L17: =F17 -> 2.4793135 | M17: =G17 -> 2.9904198 | P17: =P16+20 -> 120 | Q17: =ROUND($Q$6*P17^2+$Q$7*P17+$Q$8,1) -> 23.5 | R17: =Q17*$R$9 -> 38.6152 | S17: =R17/$B$7 -> 42.56596 | T17: =$S17*E$9 -> 14676.337 | U17: =$S17*F$9 -> 26960.403 | V17: =$S17*G$9 -> 15657.444
A18: 7 | B18: 2.165 | C18: 1.113 | D18: 1.348 | E18: =B18*$B$7/$B$6 -> 4.8532675 | F18: =C18*$B$7/$B$6 -> 2.4950054 | G18: =D18*$B$7/$B$6 -> 3.0218035 | H18: =E18 -> 4.8532675 | I18: =F18 -> 2.4950054 | J18: =G18 -> 3.0218035 | K18: =E18 -> 4.8532675 | L18: =F18 -> 2.4950054 | M18: =G18 -> 3.0218035 | P18: =P17+20 -> 140 | Q18: =ROUND($Q$6*P18^2+$Q$7*P18+$Q$8,1) -> 25.4 | R18: =Q18*$R$9 -> 41.73728 | S18: =R18/$B$7 -> 46.007463 | T18: =$S18*E$9 -> 15862.935 | U18: =$S18*F$9 -> 29140.18 | V18: =$S18*G$9 -> 16923.365
A19: 8 | B19: 2.41 | C19: 1.119 | D19: 1.362 | E19: =B19*$B$7/$B$6 -> 5.4024825 | F19: =C19*$B$7/$B$6 -> 2.5084556 | G19: =D19*$B$7/$B$6 -> 3.0531872 | H19: =E19 -> 5.4024825 | I19: =F19 -> 2.5084556 | J19: =G19 -> 3.0531872 | K19: =E19 -> 5.4024825 | L19: =F19 -> 2.5084556 | M19: =G19 -> 3.0531872 | P19: =P18+20 -> 160 | Q19: =ROUND($Q$6*P19^2+$Q$7*P19+$Q$8,1) -> 27.4 | R19: =Q19*$R$9 -> 45.02368 | S19: =R19/$B$7 -> 49.630098 | T19: =$S19*E$9 -> 17111.985 | U19: =$S19*F$9 -> 31434.683 | V19: =$S19*G$9 -> 18255.914
A20: 9 | B20: 2.655 | C20: 1.125 | D20: 1.376 | E20: =B20*$B$7/$B$6 -> 5.9516975 | F20: =C20*$B$7/$B$6 -> 2.5219057 | G20: =D20*$B$7/$B$6 -> 3.0845709 | H20: =E20 -> 5.9516975 | I20: =F20 -> 2.5219057 | J20: =G20 -> 3.0845709 | K20: =E20 -> 5.9516975 | L20: =F20 -> 2.5219057 | M20: =G20 -> 3.0845709 | P20: =P19+20 -> 180 | Q20: =ROUND($Q$6*P20^2+$Q$7*P20+$Q$8,1) -> 29.4 | R20: =Q20*$R$9 -> 48.31008 | S20: =R20/$B$7 -> 53.252733 | T20: =$S20*E$9 -> 18361.035 | U20: =$S20*F$9 -> 33729.185 | V20: =$S20*G$9 -> 19588.462
A21: 10 | B21: 2.9 | C21: 1.132 | D21: 1.39 | E21: =B21*$B$7/$B$6 -> 6.5009125 | F21: =C21*$B$7/$B$6 -> 2.5375976 | G21: =D21*$B$7/$B$6 -> 3.1159546 | H21: =E21 -> 6.5009125 | I21: =F21 -> 2.5375976 | J21: =G21 -> 3.1159546 | K21: =E21 -> 6.5009125 | L21: =F21 -> 2.5375976 | M21: =G21 -> 3.1159546 | P21: =P20+20 -> 200 | Q21: =ROUND($Q$6*P21^2+$Q$7*P21+$Q$8,1) -> 31.6 | R21: =Q21*$R$9 -> 51.92512 | S21: =R21/$B$7 -> 57.237631 | T21: =$S21*E$9 -> 19734.99 | U21: =$S21*F$9 -> 36253.138 | V21: =$S21*G$9 -> 21054.265
A22: 11 | B22: 3.145 | C22: 1.138 | D22: 1.405 | E22: =B22*$B$7/$B$6 -> 7.0501276 | F22: =C22*$B$7/$B$6 -> 2.5510477 | G22: =D22*$B$7/$B$6 -> 3.14958 | H22: 0 | I22: 0 | J22: 0 | K22: =E22 -> 7.0501276 | L22: =F22 -> 2.5510477 | M22: =G22 -> 3.14958 | P22: =P21+20 -> 220 | Q22: 34 | R22: =Q22*$R$9 -> 55.8688 | S22: =R22/$B$7 -> 61.584793 | T22: =$S22*E$9 -> 21233.849 | U22: =$S22*F$9 -> 39006.541 | V22: =$S22*G$9 -> 22653.323
A23: 12 | B23: 3.39 | C23: 1.145 | D23: 1.419 | E23: =B23*$B$7/$B$6 -> 7.5993426 | F23: =C23*$B$7/$B$6 -> 2.5667396 | G23: =D23*$B$7/$B$6 -> 3.1809638 | H23: 0 | I23: 0 | J23: 0 | K23: =E23 -> 7.5993426 | L23: =F23 -> 2.5667396 | M23: =G23 -> 3.1809638 | P23: =P22+20 -> 240 | Q23: =ROUND($Q$6*P23^2+$Q$7*P23+$Q$8,1) -> 36.1 | R23: =Q23*$R$9 -> 59.31952 | S23: =R23/$B$7 -> 65.388559 | T23: =$S23*E$9 -> 22545.352 | U23: =$S23*F$9 -> 41415.768 | V23: =$S23*G$9 -> 24052.499
A24: 13 | B24: 3.635 | C24: 1.151 | D24: 1.433 | E24: =B24*$B$7/$B$6 -> 8.1485576 | F24: =C24*$B$7/$B$6 -> 2.5801898 | G24: =D24*$B$7/$B$6 -> 3.2123475 | H24: 0 | I24: 0 | J24: 0 | K24: =E24 -> 8.1485576 | L24: =F24 -> 2.5801898 | M24: =G24 -> 3.2123475 | P24: =P23+20 -> 260 | Q24: =ROUND($Q$6*P24^2+$Q$7*P24+$Q$8,1) -> 38.5 | R24: =Q24*$R$9 -> 63.2632 | S24: =R24/$B$7 -> 69.735721 | T24: =$S24*E$9 -> 24044.212 | U24: =$S24*F$9 -> 44169.171 | V24: =$S24*G$9 -> 25651.557
A25: 14 | B25: 3.88 | C25: 1.157 | D25: 1.447 | E25: =B25*$B$7/$B$6 -> 8.6977726 | F25: =C25*$B$7/$B$6 -> 2.5936399 | G25: =D25*$B$7/$B$6 -> 3.2437312 | H25: 0 | I25: 0 | J25: 0 | K25: =E25 -> 8.6977726 | L25: =F25 -> 2.5936399 | M25: =G25 -> 3.2437312 | P25: =P24+20 -> 280 | Q25: =ROUND($Q$6*P25^2+$Q$7*P25+$Q$8,1) -> 41 | R25: =Q25*$R$9 -> 67.3712 | S25: =R25/$B$7 -> 74.264015 | T25: =$S25*E$9 -> 25605.524 | U25: =$S25*F$9 -> 47037.299 | V25: =$S25*G$9 -> 27317.243
A26: 15 | B26: 4.125 | C26: 1.164 | D26: 1.461 | E26: =B26*$B$7/$B$6 -> 9.2469877 | F26: =C26*$B$7/$B$6 -> 2.6093318 | G26: =D26*$B$7/$B$6 -> 3.2751149 | H26: 0 | I26: 0 | J26: 0 | K26: =E26 -> 9.2469877 | L26: =F26 -> 2.6093318 | M26: =G26 -> 3.2751149 | P26: =P25+20 -> 300 | Q26: =ROUND($Q$6*P26^2+$Q$7*P26+$Q$8,1) -> 43.5 | R26: =Q26*$R$9 -> 71.4792 | S26: =R26/$B$7 -> 78.792308 | T26: =$S26*E$9 -> 27166.837 | U26: =$S26*F$9 -> 49905.427 | V26: =$S26*G$9 -> 28982.928
A27: 16 | B27: 4.37 | C27: 1.17 | D27: 1.475 | E27: =B27*$B$7/$B$6 -> 9.7962027 | F27: =C27*$B$7/$B$6 -> 2.622782 | G27: =D27*$B$7/$B$6 -> 3.3064986 | H27: 0 | I27: 0 | J27: 0 | K27: =E27 -> 9.7962027 | L27: =F27 -> 2.622782 | M27: =G27 -> 3.3064986 | P27: =P26+20 -> 320 | Q27: =ROUND($Q$6*P27^2+$Q$7*P27+$Q$8,1) -> 46.1 | R27: =Q27*$R$9 -> 75.75152 | S27: =R27/$B$7 -> 83.501734 | T27: =$S27*E$9 -> 28790.602 | U27: =$S27*F$9 -> 52888.28 | V27: =$S27*G$9 -> 30715.241
A28: 17 | B28: 4.195 | C28: 1.228 | D28: 1.488 | E28: =B28*$B$7/$B$6 -> 9.4039062 | F28: =C28*$B$7/$B$6 -> 2.7528002 | G28: =D28*$B$7/$B$6 -> 3.3356406 | H28: 0 | I28: 0 | J28: 0 | K28: =E28 -> 9.4039062 | L28: =F28 -> 2.7528002 | M28: =G28 -> 3.3356406 | P28: =P27+20 -> 340 | Q28: =ROUND($Q$6*P28^2+$Q$7*P28+$Q$8,1) -> 48.8 | R28: =Q28*$R$9 -> 80.18816 | S28: =R28/$B$7 -> 88.392291 | T28: =$S28*E$9 -> 30476.819 | U28: =$S28*F$9 -> 55985.858 | V28: =$S28*G$9 -> 32514.182
A29: 18 | B29: 4.02 | C29: 1.286 | D29: 1.5 | E29: =B29*$B$7/$B$6 -> 9.0116098 | F29: =C29*$B$7/$B$6 -> 2.8828185 | G29: =D29*$B$7/$B$6 -> 3.362541 | H29: 0 | I29: 0 | J29: 0 | K29: =E29 -> 9.0116098 | L29: =F29 -> 2.8828185 | M29: =G29 -> 3.362541 | P29: =P28+20 -> 360 | Q29: =ROUND($Q$6*P29^2+$Q$7*P29+$Q$8,1) -> 51.6 | R29: =Q29*$R$9 -> 84.78912 | S29: =R29/$B$7 -> 93.46398 | T29: =$S29*E$9 -> 32225.489 | U29: =$S29*F$9 -> 59198.162 | V29: =$S29*G$9 -> 34379.75
A30: 19 | B30: 3.845 | C30: 1.344 | D30: 1.513 | E30: =B30*$B$7/$B$6 -> 8.6193133 | F30: =C30*$B$7/$B$6 -> 3.0128367 | G30: =D30*$B$7/$B$6 -> 3.391683 | H30: 0 | I30: 0 | J30: 0 | K30: =E30 -> 8.6193133 | L30: =F30 -> 3.0128367 | M30: =G30 -> 3.391683 | P30: =P29+20 -> 380 | Q30: =ROUND($Q$6*P30^2+$Q$7*P30+$Q$8,1) -> 54.5 | R30: =Q30*$R$9 -> 89.5544 | S30: =R30/$B$7 -> 98.7168 | T30: =$S30*E$9 -> 34036.612 | U30: =$S30*F$9 -> 62525.19 | V30: =$S30*G$9 -> 36311.945
A31: 20 | B31: 3.67 | C31: 1.402 | D31: 1.525 | E31: =B31*$B$7/$B$6 -> 8.2270169 | F31: =C31*$B$7/$B$6 -> 3.142855 | G31: =D31*$B$7/$B$6 -> 3.4185833 | H31: 0 | I31: 0 | J31: 0 | K31: =E31 -> 8.2270169 | L31: =F31 -> 3.142855 | M31: =G31 -> 3.4185833 | P31: =P30+20 -> 400 | Q31: =ROUND($Q$6*P31^2+$Q$7*P31+$Q$8,1) -> 57.4 | R31: =Q31*$R$9 -> 94.31968 | S31: =R31/$B$7 -> 103.96962 | T31: =$S31*E$9 -> 35847.734 | U31: =$S31*F$9 -> 65852.219 | V31: =$S31*G$9 -> 38244.14
A32: 21 | B32: 3.495 | C32: 1.46 | D32: 1.538 | E32: =B32*$B$7/$B$6 -> 7.8347205 | F32: =C32*$B$7/$B$6 -> 3.2728732 | G32: =D32*$B$7/$B$6 -> 3.4477253 | H32: 0 | I32: 0 | J32: 0 | K32: =E32 -> 7.8347205 | L32: =F32 -> 3.2728732 | M32: =G32 -> 3.4477253 | P32: =P31+20 -> 420 | Q32: =ROUND($Q$6*P32^2+$Q$7*P32+$Q$8,1) -> 60.5 | R32: =Q32*$R$9 -> 99.4136 | S32: =R32/$B$7 -> 109.5847 | T32: =$S32*E$9 -> 37783.762 | U32: =$S32*F$9 -> 69408.697 | V32: =$S32*G$9 -> 40309.59
A33: 22 | B33: 3.32 | C33: 1.518 | D33: 1.55 | E33: =B33*$B$7/$B$6 -> 7.442424 | F33: =C33*$B$7/$B$6 -> 3.4028915 | G33: =D33*$B$7/$B$6 -> 3.4746257 | H33: 0 | I33: 0 | J33: 0 | K33: =E33 -> 7.442424 | L33: =F33 -> 3.4028915 | M33: =G33 -> 3.4746257 | P33: =P32+20 -> 440 | Q33: =ROUND($Q$6*P33^2+$Q$7*P33+$Q$8,1) -> 63.6 | R33: =Q33*$R$9 -> 104.50752 | S33: =R33/$B$7 -> 115.19979 | T33: =$S33*E$9 -> 39719.789 | U33: =$S33*F$9 -> 72965.176 | V33: =$S33*G$9 -> 42375.04
A34: 23 | B34: 3.145 | C34: 1.576 | D34: 1.563 | E34: =B34*$B$7/$B$6 -> 7.0501276 | F34: =C34*$B$7/$B$6 -> 3.5329097 | G34: =D34*$B$7/$B$6 -> 3.5037677 | H34: 0 | I34: 0 | J34: 0 | K34: =E34 -> 7.0501276 | L34: =F34 -> 3.5329097 | M34: =G34 -> 3.5037677 | P34: =P33+20 -> 460 | Q34: =ROUND($Q$6*P34^2+$Q$7*P34+$Q$8,1) -> 66.7 | R34: =Q34*$R$9 -> 109.60144 | S34: =R34/$B$7 -> 120.81487 | T34: =$S34*E$9 -> 41655.816 | U34: =$S34*F$9 -> 76521.655 | V34: =$S34*G$9 -> 44440.49
A35: 24 | B35: 2.97 | C35: 1.634 | D35: 1.575 | E35: =B35*$B$7/$B$6 -> 6.6578311 | F35: =C35*$B$7/$B$6 -> 3.662928 | G35: =D35*$B$7/$B$6 -> 3.530668 | H35: 0 | I35: 0 | J35: 0 | K35: =E35 -> 6.6578311 | L35: =F35 -> 3.662928 | M35: =G35 -> 3.530668 | P35: =P34+20 -> 480 | Q35: 71.5 | R35: =Q35*$R$9 -> 117.4888 | S35: =R35/$B$7 -> 129.5092 | T35: =$S35*E$9 -> 44653.536 | U35: =$S35*F$9 -> 82028.46 | V35: =$S35*G$9 -> 47638.607
A36: 25 | B36: 2.795 | C36: 1.692 | D36: 1.588 | E36: =B36*$B$7/$B$6 -> 6.2655347 | F36: =C36*$B$7/$B$6 -> 3.7929462 | G36: =D36*$B$7/$B$6 -> 3.55981 | H36: 0 | I36: 0 | J36: 0 | K36: 0 | L36: =F36 -> 3.7929462 | M36: =G36 -> 3.55981
A37: 26 | B37: 2.62 | C37: 1.75 | D37: 1.6 | E37: =B37*$B$7/$B$6 -> 5.8732382 | F37: =C37*$B$7/$B$6 -> 3.9229645 | G37: =D37*$B$7/$B$6 -> 3.5867104 | H37: 0 | I37: 0 | J37: 0 | K37: 0 | L37: =F37 -> 3.9229645 | M37: =G37 -> 3.5867104
A38: 27 | B38: 2.551 | C38: 1.772 | D38: 1.594 | E38: =B38*$B$7/$B$6 -> 5.7185613 | F38: =C38*$B$7/$B$6 -> 3.9722817 | G38: =D38*$B$7/$B$6 -> 3.5732602 | H38: 0 | I38: 0 | J38: 0 | K38: 0 | L38: =F38 -> 3.9722817 | M38: =G38 -> 3.5732602
A39: 28 | B39: 2.482 | C39: 1.794 | D39: 1.589 | E39: =B39*$B$7/$B$6 -> 5.5638845 | F39: =C39*$B$7/$B$6 -> 4.021599 | G39: =D39*$B$7/$B$6 -> 3.5620517 | H39: 0 | I39: 0 | J39: 0 | K39: 0 | L39: =F39 -> 4.021599 | M39: =G39 -> 3.5620517
A40: 29 | B40: 2.413 | C40: 1.817 | D40: 1.583 | E40: =B40*$B$7/$B$6 -> 5.4092076 | F40: =C40*$B$7/$B$6 -> 4.073158 | G40: =D40*$B$7/$B$6 -> 3.5486016 | H40: 0 | I40: 0 | J40: 0 | K40: 0 | L40: =F40 -> 4.073158 | M40: =G40 -> 3.5486016
...

Sheet Forestry bids
A1: Worldwide cost of sequestration by forestry OBSOLETE. REPLACED WITH BUSCH ET AL DATABASE.
A2: From IPCC SR15_Chapter4_High_Res.pdf, section 4.3.7.2, and https://www.nature.com/articles/s41467-020-19578-z
A3: 1000 | B3: million hectares available
A4: 1 | B4: low Gt C/year | D4: =1000*A4/$A$3 -> 1 | E4: tons/hectare
A5: 3.7 | B5: avg Gt C/year | D5: =1000*A5/$A$3 -> 3.7 | E5: tons/hectare
A6: 17.9 | B6: high Gt C/year | D6: =1000*A6/$A$3 -> 17.9 | E6: tons/hectare
A7: -5 | B7: low tC/year | D7: I use this as the lowest value.
A8: -50 | B8: high tC/year | D8: Instead of $50, I use $US126 from the previous sheet.
A9: Note: quantities measure carbon, not carbon dioxide. See Stavins & Richards 2005, p. 38, endnote 8.
A10: Given that 500,000,000 ha are available, they most likely cannot be planted all at once.
A11: But if they can, assume the maximum bid is 500 million hectares in a year, spread equally across the 9 contracts.
A12: In reality, shorter contracts would be sublinear in cost to longer ones, because owners get their land back sooner.
A14: Tons/hectare | C14: ='Forestry timing'!E9 -> 344.79047 | D14: ='Forestry timing'!F9 -> 633.37942 | E14: ='Forestry timing'!G9 -> 367.83956 | F14: ='Forestry timing'!H9 -> 38.276925 | G14: ='Forestry timing'!I9 -> 19.939868 | H14: ='Forestry timing'!J9 -> 24.143044 | I14: ='Forestry timing'!K9 -> 153.06286 | J14: ='Forestry timing'!L9 -> 489.51871 | K14: ='Forestry timing'!M9 -> 178.10259
F15: 10-year contract | G15: 10-year contract | H15: 10-year contract | I15: 24-year contract | J15: 103-year contract | K15: 55-year contract
A16: Plantable thousand hectares/year | B16: Plantable million hectares/year, bid qty per contract | C16: $/hectare Loblolly Pine, 150 years | D16: $/hectare ponderosa pine, 150 years | E16: $/hectare black walnut, 150 years | F16: $/hectare Loblolly Pine, 10 years | G16: $/hectare ponderosa pine, 10 years | H16: $/hectare black walnut, 10 years | I16: $/hectare Loblolly Pine, 24 years | J16: $/hectare ponderosa pine, 103 years | K16: $/hectare black walnut, 55 years | L16: Save this as Forestry_bid_steps.csv
A17: 1000 | B17: =A17/9/1000 -> 0.11111111 | C17: =C14*$A$7 -> -1723.9523 | D17: =D14*$A$7 -> -3166.8971 | E17: =E14*$A$7 -> -1839.1978 | F17: =F14*$A$7 -> -191.38462 | G17: =G14*$A$7 -> -99.69934 | H17: =H14*$A$7 -> -120.71522 | I17: =I14*$A$7 -> -765.31432 | J17: =J14*$A$7 -> -2447.5936 | K17: =K14*$A$7 -> -890.51293 | L17: Linear interpolation counts rows in the spreadsheet.
A18: =A17+1000 -> 2000 | B18: =$B$17 -> 0.11111111 | C18: =C$17+(C$216-C$17)*(ROW()-ROW(C$17))/(ROW(C$216)-ROW(C$17)) -> -1801.92 | D18: =D$17+(D$216-D$17)*(ROW()-ROW(D$17))/(ROW(D$216)-ROW(D$17)) -> -3310.1236 | E18: =E$17+(E$216-E$17)*(ROW()-ROW(E$17))/(ROW(E$216)-ROW(E$17)) -> -1922.3776 | F18: =F$17+(F$216-F$17)*(ROW()-ROW(F$17))/(ROW(F$216)-ROW(F$17)) -> -200.04021 | G18: =G$17+(G$216-G$17)*(ROW()-ROW(G$17))/(ROW(G$216)-ROW(G$17)) -> -104.20836 | H18: =H$17+(H$216-H$17)*(ROW()-ROW(H$17))/(ROW(H$216)-ROW(H$17)) -> -126.1747 | I18: =I$17+(I$216-I$17)*(ROW()-ROW(I$17))/(ROW(I$216)-ROW(I$17)) -> -799.92653 | J18: =J$17+(J$216-J$17)*(ROW()-ROW(J$17))/(ROW(J$216)-ROW(J$17)) -> -2558.2888 | K18: =K$17+(K$216-K$17)*(ROW()-ROW(K$17))/(ROW(K$216)-ROW(K$17)) -> -930.78739
A19: =A18+1000 -> 3000 | B19: =$B$17 -> 0.11111111 | C19: =C$17+(C$216-C$17)*(ROW()-ROW(C$17))/(ROW(C$216)-ROW(C$17)) -> -1879.8877 | D19: =D$17+(D$216-D$17)*(ROW()-ROW(D$17))/(ROW(D$216)-ROW(D$17)) -> -3453.3501 | E19: =E$17+(E$216-E$17)*(ROW()-ROW(E$17))/(ROW(E$216)-ROW(E$17)) -> -2005.5574 | F19: =F$17+(F$216-F$17)*(ROW()-ROW(F$17))/(ROW(F$216)-ROW(F$17)) -> -208.6958 | G19: =G$17+(G$216-G$17)*(ROW()-ROW(G$17))/(ROW(G$216)-ROW(G$17)) -> -108.71737 | H19: =H$17+(H$216-H$17)*(ROW()-ROW(H$17))/(ROW(H$216)-ROW(H$17)) -> -131.63419 | I19: =I$17+(I$216-I$17)*(ROW()-ROW(I$17))/(ROW(I$216)-ROW(I$17)) -> -834.53874 | J19: =J$17+(J$216-J$17)*(ROW()-ROW(J$17))/(ROW(J$216)-ROW(J$17)) -> -2668.9839 | K19: =K$17+(K$216-K$17)*(ROW()-ROW(K$17))/(ROW(K$216)-ROW(K$17)) -> -971.06184
A20: =A19+1000 -> 4000 | B20: =$B$17 -> 0.11111111 | C20: =C$17+(C$216-C$17)*(ROW()-ROW(C$17))/(ROW(C$216)-ROW(C$17)) -> -1957.8554 | D20: =D$17+(D$216-D$17)*(ROW()-ROW(D$17))/(ROW(D$216)-ROW(D$17)) -> -3596.5766 | E20: =E$17+(E$216-E$17)*(ROW()-ROW(E$17))/(ROW(E$216)-ROW(E$17)) -> -2088.7372 | F20: =F$17+(F$216-F$17)*(ROW()-ROW(F$17))/(ROW(F$216)-ROW(F$17)) -> -217.35138 | G20: =G$17+(G$216-G$17)*(ROW()-ROW(G$17))/(ROW(G$216)-ROW(G$17)) -> -113.22639 | H20: =H$17+(H$216-H$17)*(ROW()-ROW(H$17))/(ROW(H$216)-ROW(H$17)) -> -137.09367 | I20: =I$17+(I$216-I$17)*(ROW()-ROW(I$17))/(ROW(I$216)-ROW(I$17)) -> -869.15094 | J20: =J$17+(J$216-J$17)*(ROW()-ROW(J$17))/(ROW(J$216)-ROW(J$17)) -> -2779.6791 | K20: =K$17+(K$216-K$17)*(ROW()-ROW(K$17))/(ROW(K$216)-ROW(K$17)) -> -1011.3363
A21: =A20+1000 -> 5000 | B21: =$B$17 -> 0.11111111 | C21: =C$17+(C$216-C$17)*(ROW()-ROW(C$17))/(ROW(C$216)-ROW(C$17)) -> -2035.8231 | D21: =D$17+(D$216-D$17)*(ROW()-ROW(D$17))/(ROW(D$216)-ROW(D$17)) -> -3739.8031 | E21: =E$17+(E$216-E$17)*(ROW()-ROW(E$17))/(ROW(E$216)-ROW(E$17)) -> -2171.917 | F21: =F$17+(F$216-F$17)*(ROW()-ROW(F$17))/(ROW(F$216)-ROW(F$17)) -> -226.00697 | G21: =G$17+(G$216-G$17)*(ROW()-ROW(G$17))/(ROW(G$216)-ROW(G$17)) -> -117.7354 | H21: =H$17+(H$216-H$17)*(ROW()-ROW(H$17))/(ROW(H$216)-ROW(H$17)) -> -142.55315 | I21: =I$17+(I$216-I$17)*(ROW()-ROW(I$17))/(ROW(I$216)-ROW(I$17)) -> -903.76315 | J21: =J$17+(J$216-J$17)*(ROW()-ROW(J$17))/(ROW(J$216)-ROW(J$17)) -> -2890.3743 | K21: =K$17+(K$216-K$17)*(ROW()-ROW(K$17))/(ROW(K$216)-ROW(K$17)) -> -1051.6107
A22: =A21+1000 -> 6000 | B22: =$B$17 -> 0.11111111 | C22: =C$17+(C$216-C$17)*(ROW()-ROW(C$17))/(ROW(C$216)-ROW(C$17)) -> -2113.7908 | D22: =D$17+(D$216-D$17)*(ROW()-ROW(D$17))/(ROW(D$216)-ROW(D$17)) -> -3883.0296 | E22: =E$17+(E$216-E$17)*(ROW()-ROW(E$17))/(ROW(E$216)-ROW(E$17)) -> -2255.0968 | F22: =F$17+(F$216-F$17)*(ROW()-ROW(F$17))/(ROW(F$216)-ROW(F$17)) -> -234.66255 | G22: =G$17+(G$216-G$17)*(ROW()-ROW(G$17))/(ROW(G$216)-ROW(G$17)) -> -122.24442 | H22: =H$17+(H$216-H$17)*(ROW()-ROW(H$17))/(ROW(H$216)-ROW(H$17)) -> -148.01263 | I22: =I$17+(I$216-I$17)*(ROW()-ROW(I$17))/(ROW(I$216)-ROW(I$17)) -> -938.37535 | J22: =J$17+(J$216-J$17)*(ROW()-ROW(J$17))/(ROW(J$216)-ROW(J$17)) -> -3001.0695 | K22: =K$17+(K$216-K$17)*(ROW()-ROW(K$17))/(ROW(K$216)-ROW(K$17)) -> -1091.8852
A23: =A22+1000 -> 7000 | B23: =$B$17 -> 0.11111111 | C23: =C$17+(C$216-C$17)*(ROW()-ROW(C$17))/(ROW(C$216)-ROW(C$17)) -> -2191.7585 | D23: =D$17+(D$216-D$17)*(ROW()-ROW(D$17))/(ROW(D$216)-ROW(D$17)) -> -4026.2561 | E23: =E$17+(E$216-E$17)*(ROW()-ROW(E$17))/(ROW(E$216)-ROW(E$17)) -> -2338.2766 | F23: =F$17+(F$216-F$17)*(ROW()-ROW(F$17))/(ROW(F$216)-ROW(F$17)) -> -243.31814 | G23: =G$17+(G$216-G$17)*(ROW()-ROW(G$17))/(ROW(G$216)-ROW(G$17)) -> -126.75343 | H23: =H$17+(H$216-H$17)*(ROW()-ROW(H$17))/(ROW(H$216)-ROW(H$17)) -> -153.47211 | I23: =I$17+(I$216-I$17)*(ROW()-ROW(I$17))/(ROW(I$216)-ROW(I$17)) -> -972.98756 | J23: =J$17+(J$216-J$17)*(ROW()-ROW(J$17))/(ROW(J$216)-ROW(J$17)) -> -3111.7647 | K23: =K$17+(K$216-K$17)*(ROW()-ROW(K$17))/(ROW(K$216)-ROW(K$17)) -> -1132.1597
A24: =A23+1000 -> 8000 | B24: =$B$17 -> 0.11111111 | C24: =C$17+(C$216-C$17)*(ROW()-ROW(C$17))/(ROW(C$216)-ROW(C$17)) -> -2269.7262 | D24: =D$17+(D$216-D$17)*(ROW()-ROW(D$17))/(ROW(D$216)-ROW(D$17)) -> -4169.4826 | E24: =E$17+(E$216-E$17)*(ROW()-ROW(E$17))/(ROW(E$216)-ROW(E$17)) -> -2421.4564 | F24: =F$17+(F$216-F$17)*(ROW()-ROW(F$17))/(ROW(F$216)-ROW(F$17)) -> -251.97373 | G24: =G$17+(G$216-G$17)*(ROW()-ROW(G$17))/(ROW(G$216)-ROW(G$17)) -> -131.26245 | H24: =H$17+(H$216-H$17)*(ROW()-ROW(H$17))/(ROW(H$216)-ROW(H$17)) -> -158.9316 | I24: =I$17+(I$216-I$17)*(ROW()-ROW(I$17))/(ROW(I$216)-ROW(I$17)) -> -1007.5998 | J24: =J$17+(J$216-J$17)*(ROW()-ROW(J$17))/(ROW(J$216)-ROW(J$17)) -> -3222.4599 | K24: =K$17+(K$216-K$17)*(ROW()-ROW(K$17))/(ROW(K$216)-ROW(K$17)) -> -1172.4341
A25: =A24+1000 -> 9000 | B25: =$B$17 -> 0.11111111 | C25: =C$17+(C$216-C$17)*(ROW()-ROW(C$17))/(ROW(C$216)-ROW(C$17)) -> -2347.6939 | D25: =D$17+(D$216-D$17)*(ROW()-ROW(D$17))/(ROW(D$216)-ROW(D$17)) -> -4312.7092 | E25: =E$17+(E$216-E$17)*(ROW()-ROW(E$17))/(ROW(E$216)-ROW(E$17)) -> -2504.6362 | F25: =F$17+(F$216-F$17)*(ROW()-ROW(F$17))/(ROW(F$216)-ROW(F$17)) -> -260.62931 | G25: =G$17+(G$216-G$17)*(ROW()-ROW(G$17))/(ROW(G$216)-ROW(G$17)) -> -135.77146 | H25: =H$17+(H$216-H$17)*(ROW()-ROW(H$17))/(ROW(H$216)-ROW(H$17)) -> -164.39108 | I25: =I$17+(I$216-I$17)*(ROW()-ROW(I$17))/(ROW(I$216)-ROW(I$17)) -> -1042.212 | J25: =J$17+(J$216-J$17)*(ROW()-ROW(J$17))/(ROW(J$216)-ROW(J$17)) -> -3333.1551 | K25: =K$17+(K$216-K$17)*(ROW()-ROW(K$17))/(ROW(K$216)-ROW(K$17)) -> -1212.7086
A26: =A25+1000 -> 10000 | B26: =$B$17 -> 0.11111111 | C26: =C$17+(C$216-C$17)*(ROW()-ROW(C$17))/(ROW(C$216)-ROW(C$17)) -> -2425.6616 | D26: =D$17+(D$216-D$17)*(ROW()-ROW(D$17))/(ROW(D$216)-ROW(D$17)) -> -4455.9357 | E26: =E$17+(E$216-E$17)*(ROW()-ROW(E$17))/(ROW(E$216)-ROW(E$17)) -> -2587.816 | F26: =F$17+(F$216-F$17)*(ROW()-ROW(F$17))/(ROW(F$216)-ROW(F$17)) -> -269.2849 | G26: =G$17+(G$216-G$17)*(ROW()-ROW(G$17))/(ROW(G$216)-ROW(G$17)) -> -140.28048 | H26: =H$17+(H$216-H$17)*(ROW()-ROW(H$17))/(ROW(H$216)-ROW(H$17)) -> -169.85056 | I26: =I$17+(I$216-I$17)*(ROW()-ROW(I$17))/(ROW(I$216)-ROW(I$17)) -> -1076.8242 | J26: =J$17+(J$216-J$17)*(ROW()-ROW(J$17))/(ROW(J$216)-ROW(J$17)) -> -3443.8502 | K26: =K$17+(K$216-K$17)*(ROW()-ROW(K$17))/(ROW(K$216)-ROW(K$17)) -> -1252.983
A27: =A26+1000 -> 11000 | B27: =$B$17 -> 0.11111111 | C27: =C$17+(C$216-C$17)*(ROW()-ROW(C$17))/(ROW(C$216)-ROW(C$17)) -> -2503.6293 | D27: =D$17+(D$216-D$17)*(ROW()-ROW(D$17))/(ROW(D$216)-ROW(D$17)) -> -4599.1622 | E27: =E$17+(E$216-E$17)*(ROW()-ROW(E$17))/(ROW(E$216)-ROW(E$17)) -> -2670.9958 | F27: =F$17+(F$216-F$17)*(ROW()-ROW(F$17))/(ROW(F$216)-ROW(F$17)) -> -277.94048 | G27: =G$17+(G$216-G$17)*(ROW()-ROW(G$17))/(ROW(G$216)-ROW(G$17)) -> -144.78949 | H27: =H$17+(H$216-H$17)*(ROW()-ROW(H$17))/(ROW(H$216)-ROW(H$17)) -> -175.31004 | I27: =I$17+(I$216-I$17)*(ROW()-ROW(I$17))/(ROW(I$216)-ROW(I$17)) -> -1111.4364 | J27: =J$17+(J$216-J$17)*(ROW()-ROW(J$17))/(ROW(J$216)-ROW(J$17)) -> -3554.5454 | K27: =K$17+(K$216-K$17)*(ROW()-ROW(K$17))/(ROW(K$216)-ROW(K$17)) -> -1293.2575
A28: =A27+1000 -> 12000 | B28: =$B$17 -> 0.11111111 | C28: =C$17+(C$216-C$17)*(ROW()-ROW(C$17))/(ROW(C$216)-ROW(C$17)) -> -2581.597 | D28: =D$17+(D$216-D$17)*(ROW()-ROW(D$17))/(ROW(D$216)-ROW(D$17)) -> -4742.3887 | E28: =E$17+(E$216-E$17)*(ROW()-ROW(E$17))/(ROW(E$216)-ROW(E$17)) -> -2754.1756 | F28: =F$17+(F$216-F$17)*(ROW()-ROW(F$17))/(ROW(F$216)-ROW(F$17)) -> -286.59607 | G28: =G$17+(G$216-G$17)*(ROW()-ROW(G$17))/(ROW(G$216)-ROW(G$17)) -> -149.29851 | H28: =H$17+(H$216-H$17)*(ROW()-ROW(H$17))/(ROW(H$216)-ROW(H$17)) -> -180.76953 | I28: =I$17+(I$216-I$17)*(ROW()-ROW(I$17))/(ROW(I$216)-ROW(I$17)) -> -1146.0486 | J28: =J$17+(J$216-J$17)*(ROW()-ROW(J$17))/(ROW(J$216)-ROW(J$17)) -> -3665.2406 | K28: =K$17+(K$216-K$17)*(ROW()-ROW(K$17))/(ROW(K$216)-ROW(K$17)) -> -1333.5319
A29: =A28+1000 -> 13000 | B29: =$B$17 -> 0.11111111 | C29: =C$17+(C$216-C$17)*(ROW()-ROW(C$17))/(ROW(C$216)-ROW(C$17)) -> -2659.5647 | D29: =D$17+(D$216-D$17)*(ROW()-ROW(D$17))/(ROW(D$216)-ROW(D$17)) -> -4885.6152 | E29: =E$17+(E$216-E$17)*(ROW()-ROW(E$17))/(ROW(E$216)-ROW(E$17)) -> -2837.3554 | F29: =F$17+(F$216-F$17)*(ROW()-ROW(F$17))/(ROW(F$216)-ROW(F$17)) -> -295.25166 | G29: =G$17+(G$216-G$17)*(ROW()-ROW(G$17))/(ROW(G$216)-ROW(G$17)) -> -153.80752 | H29: =H$17+(H$216-H$17)*(ROW()-ROW(H$17))/(ROW(H$216)-ROW(H$17)) -> -186.22901 | I29: =I$17+(I$216-I$17)*(ROW()-ROW(I$17))/(ROW(I$216)-ROW(I$17)) -> -1180.6608 | J29: =J$17+(J$216-J$17)*(ROW()-ROW(J$17))/(ROW(J$216)-ROW(J$17)) -> -3775.9358 | K29: =K$17+(K$216-K$17)*(ROW()-ROW(K$17))/(ROW(K$216)-ROW(K$17)) -> -1373.8064
... A215: =A214+1000 -> 199000 | B215: =$B$17 -> 0.11111111 | C215: =C$17+(C$216-C$17)*(ROW()-ROW(C$17))/(ROW(C$216)-ROW(C$17)) -> -17161.556 | D215: =D$17+(D$216-D$17)*(ROW()-ROW(D$17))/(ROW(D$216)-ROW(D$17)) -> -31525.745 | E215: =E$17+(E$216-E$17)*(ROW()-ROW(E$17))/(ROW(E$216)-ROW(E$17)) -> -18308.798 | F215: =F$17+(F$216-F$17)*(ROW()-ROW(F$17))/(ROW(F$216)-ROW(F$17)) -> -1905.1906 | G215: =G$17+(G$216-G$17)*(ROW()-ROW(G$17))/(ROW(G$216)-ROW(G$17)) -> -992.48438 | H215: =H$17+(H$216-H$17)*(ROW()-ROW(H$17))/(ROW(H$216)-ROW(H$17)) -> -1201.6927 | I215: =I$17+(I$216-I$17)*(ROW()-ROW(I$17))/(ROW(I$216)-ROW(I$17)) -> -7618.531 | J215: =J$17+(J$216-J$17)*(ROW()-ROW(J$17))/(ROW(J$216)-ROW(J$17)) -> -24365.241 | K215: =K$17+(K$216-K$17)*(ROW()-ROW(K$17))/(ROW(K$216)-ROW(K$17)) -> -8864.8549
A216: =A215+1000 -> 200000 | B216: =$B$17 -> 0.11111111 | C216: ='Forestry timing'!E9*$A$8 -> -17239.523 | D216: ='Forestry timing'!F9*$A$8 -> -31668.971 | E216: ='Forestry timing'!G9*$A$8 -> -18391.978 | F216: ='Forestry timing'!H9*$A$8 -> -1913.8462 | G216: ='Forestry timing'!I9*$A$8 -> -996.9934 | H216: ='Forestry timing'!J9*$A$8 -> -1207.1522 | I216: ='Forestry timing'!K9*$A$8 -> -7653.1432 | J216: ='Forestry timing'!L9*$A$8 -> -24475.936 | K216: ='Forestry timing'!M9*$A$8 -> -8905.1293

Sheet Agriculture
A1: From Smith P., et ak, 2014: Agriculture, Forestry and Other Land Use (AFOLU). In: Climate Change 2014: Mitigation of Climate Change, Figure 11.17.
A2: Smith P., M. Bustamante, H. Ahammad, H. Clark, H. Dong, E. A. Elsiddig, H. Haberl, R. Harper, J. House, M. Jafari, O. Masera, C. Mbow, N. H. Ravindranath, C. W. Rice, C. Robledo Abad, A. Romanovskaya, F. Sperling, and F. Tubiello, 2014: Agriculture, Forestry and Other Land Use (AFOLU). In: Climate Change 2014: Mitigation of Climate Change. Contribution of Working Group III to the Fifth Assessment Report of the Intergovernmental Panel on Climate Change [Edenhofer, O., R. Pichs-Madruga, Y. Sokona, E. Farahani, S. Kadner, K. Seyboth, A. Adler, I. Baum, S. Brunner, P. Eickemeier, B. Kriemann, J. Savolainen, S. Schlömer, C. von Stechow, T. Zwickel and J.C. Minx (eds.)]. Cambridge University Press, Cambridge, United Kingdom and New York, NY, USA.
A3: Because Hector uses units of teragrams (same as gigatons) carbon rather than carbon dioxide, we must divide the quantities by 3.66406 = gCO2/gC. Further,SMDAMAGE uses megatons C rather than gigatons C, so multiply by 1000.
B7: GtCO2/year
A8: OECD $20 | B8: 0.36 | C8: 20
A9: OECD $50 | B9: 0.59 | C9: 50
A10: OECD $100 | B10: 0.95 | C10: 100
A11: EIT $20 | B11: 0.155 | C11: 20
A12: EIT $50 | B12: 0.24 | C12: 50
A13: EIT $100 | B13: 0.35 | C13: 100
A14: LAM $20 | B14: 0.22 | C14: 20
A15: LAM $50 | B15: 0.38 | C15: 50
A16: LAM $100 | B16: 0.58 | C16: 100
A17: MAF $20 | B17: 0.18 | C17: 20
A18: MAF $50 | B18: 0.35 | C18: 50
A19: MAF $100 | B19: 0.6 | C19: 100
... A22: ASIA $100 | B22: 1.82 | C22: 100
A25: Bid stack | B25: GtCO2/year
A26: 20 | B26: 0.36
A27: 20 | B27: 0.155
A28: 20 | B28: 0.22
A29: 20 | B29: 0.18
A30: 20 | B30: 0.78
A31: 50 | B31: 0.59
A32: 50 | B32: 0.24
A33: 50 | B33: 0.38
A34: 50 | B34: 0.35
A35: 50 | B35: 1.2
A36: 100 | B36: 0.95
A37: 100 | B37: 0.35
... A40: 100 | B40: 1.82
A42: Eliminate duplicates and convert Gt to Mt. Fit a curve.
A43: 20 | B43: =SUMIF($A$26:$A$40,A43,$B$26:$B$40)*1000 -> 1695
A44: 50 | B44: =SUMIF($A$26:$A$40,A44,$B$26:$B$40)*1000 -> 2760
